Workbook
Name age: Inputs!$B$2
Name healthStatus: Inputs!$B$5
Name Kainput_curve: Inputs!$B$10:$AO$10
Name Kinput_inputs: API!$A$3:$D$8
Name sex: Inputs!$B$3
Name smoker: Inputs!$B$4
Name Xinput_curve: Inputs!$B$9:$AO$10
Name Xjinput_inputs: Inputs!$A$2:$B$7
Name Xoutput_monthlyPremium: Output!$B$3
Name Xoutput_outputs: Output!$A$5:$AO$7

Sheet API
B1: Value | C1: Schema | D1: Description
A2: Inputs
A3: age | C3: {"type": "number", "maximum": 85, "minimum": 18, "required": true }
A4: sex | B4: M | C4: {"enum": ["M","F"]}
A5: smoker | B5: FALSE | C5: { "type": "boolean" }
A6: healthStatus | B6: 1 | C6: {"type": "number", "maximum": 3, "minimum": 1}
A7: lastYearOfPolicyAge | C7: {"type": "number", "maximum": 90, "minimum": 25, "required": true}
A8: permanentCoverage | C8: {"type": "number", "minimum": 0}

Sheet Inputs
A2: age | B2: =API!B3 -> 0
A3: sex | B3: =API!B4 -> M
A4: smoker | B4: =IF(API!B5, "Yes", "No") -> No
A5: healthStatus | B5: =API!B6 -> 1
A6: lastYearOfPolicyAge | B6: =API!B7 -> 0
A7: permanentCoverage | B7: =API!B8 -> 0
A9: year | B9: 1 | C9: =B9+1 -> 2 | D9: =C9+1 -> 3 | E9: =D9+1 -> 4 | F9: =E9+1 -> 5 | G9: =F9+1 -> 6 | H9: =G9+1 -> 7 | I9: =H9+1 -> 8 | J9: =I9+1 -> 9 | ... AO9: =AN9+1 -> 40
A10: curve | B10: 842000 | C10: 837000 | D10: 830000 | E10: 821000 | F10: 811000 | G10: 798000 | H10: 784000 | I10: 767000 | J10: 747000 | K10: 725000 | L10: 699000 | M10: 671000 | N10: 639000 | O10: 604000 | P10: 565000 | Q10: 522000 | R10: 475000 | S10: 423000 | T10: 367000 | U10: 305000 | V10: 238000 | W10: 165000 | X10: 86000 | Y10: 0 | Z10: 0 | AA10: 0 | AB10: 0 | AC10: 0 | AD10: 0 | AE10: 0 | AF10: 0 | AG10: 0 | AH10: 0 | AI10: 0 | AJ10: 0 | AK10: 0 | AL10: 0 | AM10: 0 | AN10: 0 | AO10: 0

Sheet Output
A3: Monthly Premium | B3: =Pricing!M23 -> #N/A
A5: key | B5: Year1 | C5: Year2 | D5: Year3 | E5: Year4 | F5: Year5 | G5: Year6 | H5: Year7 | I5: Year8 | J5: Year9 | K5: Year10 | L5: Year11 | M5: Year12 | N5: Year13 | O5: Year14 | P5: Year15 | Q5: Year16 | R5: Year17 | S5: Year18 | T5: Year19 | U5: Year20 | V5: Year21 | W5: Year22 | X5: Year23 | Y5: Year24 | Z5: Year25 | AA5: Year26 | AB5: Year27 | AC5: Year28 | AD5: Year29 | AE5: Year30 | AF5: Year31 | AG5: Year32 | AH5: Year33 | AI5: Year34 | AJ5: Year35 | AK5: Year36 | AL5: Year37 | AM5: Year38 | AN5: Year39 | AO5: Year40
A6: age | B6: =Pricing!B36 -> 0 | C6: =Pricing!C36 -> 1 | D6: =Pricing!D36 -> 2 | E6: =Pricing!E36 -> 3 | F6: =Pricing!F36 -> 4 | G6: =Pricing!G36 -> 5 | H6: =Pricing!H36 -> 6 | I6: =Pricing!I36 -> 7 | ... AO6: =Pricing!AO36 -> 39
A7: curve | B7: =Pricing!B39 -> 842000 | C7: =Pricing!C39 -> 837000 | D7: =Pricing!D39 -> 830000 | E7: =Pricing!E39 -> 821000 | F7: =Pricing!F39 -> 811000 | G7: =Pricing!G39 -> 798000 | H7: =Pricing!H39 -> 784000 | I7: =Pricing!I39 -> 767000 | ... AO7: =Pricing!AO39 -> 0

Sheet Assms
A1: Level prem years requested | B1: =SUM(B4:AO4) -> 23
B2: 1 | C2: =B2+1 -> 2 | D2: =C2+1 -> 3 | E2: =D2+1 -> 4 | F2: =E2+1 -> 5 | G2: =F2+1 -> 6 | H2: =G2+1 -> 7 | I2: =H2+1 -> 8 | J2: =I2+1 -> 9 | ... AO2: =AN2+1 -> 40
A3: Raw benefit amount | B3: =MAX(Inputs!B10-Inputs!$B$7,0) -> 842000 | C3: =MAX(Inputs!C10-Inputs!$B$7,0) -> 837000 | D3: =MAX(Inputs!D10-Inputs!$B$7,0) -> 830000 | E3: =MAX(Inputs!E10-Inputs!$B$7,0) -> 821000 | F3: =MAX(Inputs!F10-Inputs!$B$7,0) -> 811000 | G3: =MAX(Inputs!G10-Inputs!$B$7,0) -> 798000 | H3: =MAX(Inputs!H10-Inputs!$B$7,0) -> 784000 | I3: =MAX(Inputs!I10-Inputs!$B$7,0) -> 767000 | ... AO3: =MAX(Inputs!AO10-Inputs!$B$7,0) -> 0
A4: Years requested | B4: =IF(B3>0,1,0) -> 1 | C4: =IF(C3>0,1,0) -> 1 | D4: =IF(D3>0,1,0) -> 1 | E4: =IF(E3>0,1,0) -> 1 | F4: =IF(F3>0,1,0) -> 1 | G4: =IF(G3>0,1,0) -> 1 | H4: =IF(H3>0,1,0) -> 1 | I4: =IF(I3>0,1,0) -> 1 | ... AO4: =IF(AO3>0,1,0) -> 0
A5: Adjust once zero | B5: =B3 -> 842000 | C5: =IF(B5=0,0,C3) -> 837000 | D5: =IF(C5=0,0,D3) -> 830000 | E5: =IF(D5=0,0,E3) -> 821000 | F5: =IF(E5=0,0,F3) -> 811000 | G5: =IF(F5=0,0,G3) -> 798000 | H5: =IF(G5=0,0,H3) -> 784000 | I5: =IF(H5=0,0,I3) -> 767000 | J5: =IF(I5=0,0,J3) -> 747000 | ... AO5: =IF(AN5=0,0,AO3) -> 0
A6: Final benefit amount | B6: =IF(B2<=$B$1,B5,0) -> 842000 | C6: =IF(C2<=$B$1,C5,0) -> 837000 | D6: =IF(D2<=$B$1,D5,0) -> 830000 | E6: =IF(E2<=$B$1,E5,0) -> 821000 | F6: =IF(F2<=$B$1,F5,0) -> 811000 | G6: =IF(G2<=$B$1,G5,0) -> 798000 | H6: =IF(H2<=$B$1,H5,0) -> 784000 | I6: =IF(I2<=$B$1,I5,0) -> 767000 | ... AO6: =IF(AO2<=$B$1,AO5,0) -> 0
A7: Indicator of year active | B7: =IF(B5>0,1,"") -> 1 | C7: =IF(C5>0,1,"") -> 1 | D7: =IF(D5>0,1,"") -> 1 | E7: =IF(E5>0,1,"") -> 1 | F7: =IF(F5>0,1,"") -> 1 | G7: =IF(G5>0,1,"") -> 1 | H7: =IF(H5>0,1,"") -> 1 | I7: =IF(I5>0,1,"") -> 1 | ... AO7: =IF(AO5>0,1,"")
A8: Total number years | B8: =SUM(B7:AO7) -> 23
A9: Change since issue: | B9: 0 | C9: =IF(C6="","",IF(C6=0,0,C6/$B$6-1)) -> -0.0059382423 | D9: =IF(D6="","",IF(D6=0,0,D6/$B$6-1)) -> -0.014251781 | E9: =IF(E6="","",IF(E6=0,0,E6/$B$6-1)) -> -0.024940618 | F9: =IF(F6="","",IF(F6=0,0,F6/$B$6-1)) -> -0.036817102 | G9: =IF(G6="","",IF(G6=0,0,G6/$B$6-1)) -> -0.052256532 | H9: =IF(H6="","",IF(H6=0,0,H6/$B$6-1)) -> -0.06888361 | I9: =IF(I6="","",IF(I6=0,0,I6/$B$6-1)) -> -0.089073634 | J9: =IF(J6="","",IF(J6=0,0,J6/$B$6-1)) -> -0.1128266 | ... AO9: =IF(AO6="","",IF(AO6=0,0,AO6/$B$6-1)) -> 0
A11: Expenses and commissions | M11: Unitized Premium Increase | N11: Total Lapse Rate | R11: Issue Age | S11: Margin level | T11: Margin custom
A12: First year marketing & sales costs | C12: 1.7 | E12: Automated UW slippage | I12: Investment yield | K12: 0.06 | M12: 0 | N12: 0 | R12: 0 | S12: 0.3 | T12: 0.2
A13: kmodo license fee | C13: =C26-C27 -> 0.08 | E13: Max age | F13: FA limit | G13: Mort load | I13: Corporate tax rate | K13: 0.28 | M13: =M14-0.025 -> 1 | N13: 0 | R13: 25 | S13: 0.3 | T13: 0.2
A14: Total FY | C14: =C12+C13 -> 1.78 | E14: 50 | F14: 2000000 | G14: 0.06 | I14: Discount rate for prem est: | K14: =K12 -> 0.06 | M14: 1.025 | N14: 0.020634286 | R14: 30 | S14: 0.15 | T14: 0.22
E15: 60 | F15: 1000000 | G15: 0.06 | M15: 1.05 | N15: 0.041268571 | P15: Example: | R15: 35 | S15: 0.1 | T15: 0.13
A16: Premium tax | C16: 0.02 | E16: Applicable mortality load | G16: =IF(age<=E14,IF(Assms!C37<=F14,Assms!G14,0),IF(age<=E15,IF(Assms!C37<=F15,G15,0))) -> 0.06 | I16: Targeted profit margin | K16: 0.06 | M16: 1.075 | N16: 0.061902857 | R16: 40 | S16: 0.11 | T16: 0.13
A17: Commissions | C17: 0.02 | M17: 1.1 | N17: 0.082537143 | P17: Face (t-1) | Q17: 1000000 | R17: 45 | S17: 0.12 | T17: 0.13
A18: kmodo license fee | C18: =C27 -> 0.02 | I18: Margin gross up factor | K18: =IF(G19="Yes",VLOOKUP(C33,R12:T22,2),VLOOKUP(C33,R12:T22,3)) -> 0.2 | M18: 1.125 | N18: 0.10317143 | P18: Face (t) | Q18: 900000 | R18: 50 | S18: 0.15 | T18: 0.13
A19: Expenses as % premium (all years) | C19: =SUM(C16:C18) -> 0.06 | I19: (initial guess before iteration) | M19: 1.15 | N19: 0.12380571 | R19: 55 | S19: 0.16 | T19: 0.16
M20: 1.175 | N20: 0.14444 | P20: Unitied P Incr | Q20: =IF(Q3=0,0,ROUND(Q17 / Q18 * 40,0)/40) -> 1.1 | R20: 60 | S20: 0.16 | T20: 0.16
A21: Per policy issue expenses | C21: =VLOOKUP(C33,A41:B50,2) -> 75 | I21: DMD Effectiveness factor: | K21: 0.5 | M21: 1.2 | N21: 0.14444 | P21: Tot Lapse rate | Q21: =VLOOKUP(Q20,Assms!$M$13:$N$173,2) -> 0.082537143 | R21: 65 | S21: 0.16 | T21: 0.16
A22: Per policy administrative expenses | C22: 75 | F22: Mortality | G22: Lapse | M22: 1.225 | N22: 0.14444 | R22: 100 | S22: 0.16 | T22: 0.16
A23: Annual inflation rate | C23: 0.02 | E23: Super preferred NT | F23: 1 | G23: 1 | I23: Statutory reserving Lx margin | K23: 0.5 | M23: 1.25 | N23: 0.162495
E24: Preferred NT | F24: 2 | G24: 2 | M24: 1.275 | N24: 0.162495
A25: kmodo license fee | C25: Applicable? | E25: Standard Plus NT | F25: 3 | G25: 3 | I25: How RBC factor is applied: | K25: RBC factors: | M25: 1.3 | N25: 0.162495
A26: Year 1 | B26: 0.1 | C26: =IF($B$28=0,0,B26) -> 0.1 | E26: Standard NT | F26: 4 | G26: 3 | I26: Statutory reserve | K26: 0.02 | M26: 1.325 | N26: 0.162495
A27: Year 2-20 | B27: 0.02 | C27: =IF($B$28=0,0,B27) -> 0.02 | E27: Preferred Tobacco | F27: 5 | G27: 4 | I27: Death benefit | K27: 0.002 | M27: 1.35 | N27: 0.18055
A28: Std Dev FA | B28: =_xlfn.STDEV.P(B9:AO9) -> 0.25082705 | E28: Standard Tobacco | F28: 6 | G28: 4 | I28: Gross premium | K28: 0.08 | M28: 1.375 | N28: 0.18055
A29: (if std dev = 0, level FA therefore no license fee) | I29: Only for IRR calc; does not affect prem quote | M29: 1.4 | N29: 0.18055
E30: Face amt | F30: Lx Code | G30: Qx code | M30: 1.425 | N30: 0.18055
A31: Non-commissionable policy fee | C31: 75 | E31: 0 | F31: 1 | G31: 1 | I31: Mortality improvement/year | K31: 0.01 | M31: 1.45 | N31: 0.198605
E32: 250000 | F32: 2 | G32: 2 | M32: 1.475 | N32: 0.198605
A33: Issue age: | C33: =age -> 0 | E33: 500000 | F33: 3 | G33: 2 | M33: 1.5 | N33: 0.198605
A34: Term length | C34: =B8 -> 23 | E34: 1000000 | F34: 4 | G34: 3 | M34: 1.525 | N34: 0.198605
A35: Underwriting code | C35: =IF(smoker="No",healthStatus,IF(healthStatus=3,6,5)) -> 1 | E35: 2000000 | F35: 5 | G35: 3 | M35: 1.55 | N35: 0.198605
A36: Lapse table code | C36: =VLOOKUP(C35,F23:G28,2) -> 1 | E36: 5000000 | F36: 6 | G36: 4 | M36: 1.575 | N36: 0.21666
A37: Face amount | C37: =B6 -> 842000 | E37: Selected | F37: =VLOOKUP($C$37,E31:G36,2) -> 3 | G37: =VLOOKUP($C$37,E31:G36,3) -> 2 | M37: 1.6 | N37: 0.21666
A38: Gender | C38: =sex -> M | M38: 1.625 | N38: 0.21666
E39: NOTE: minimum face amount in any policy duration is set in the benefit model. | M39: 1.65 | N39: 0.21666
A40: Issue Age | B40: Per Policy Exp | E40: This minimum is important to ensure no cash values. | M40: 1.675 | N40: 0.234715
A41: 0 | B41: 75 | E41: Use this model to test for the necessary limits. | M41: 1.7 | N41: 0.234715
...

Sheet Pricing
C1: Custom Benefits level premium determination | J1: Last year of coverage requested (BOY age): | M1: =Inputs!B6 -> 0
C2: Base lapses | E2: With Excess | G2: + Mort det | J2: Last year of custom benefit (BOY age) | M2: =age+Pricing!M4-1 -> 22 | N2: EG could be shorter period than requested
A3: PV death claims | C3: =NPV(Assms!K14,$B51:$AO51) -> #N/A | E3: =NPV(Assms!$K$14,$B64:$AO64) -> #N/A | G3: =NPV(Assms!$K$14,$B77:$AO77) -> #N/A | J3: Last year of coverage priced/shown | M3: =MIN(M1,M2) -> 0 | N3: Lessor of above
A4: Annualizing factor | C4: =NPV(Assms!$K$14,$C$48:$AO$48)+$B$48 -> #N/A | E4: =NPV(Assms!$K$14,$C$61:$AO$61)+$B$61 -> #N/A | G4: =NPV(Assms!$K$14,$C$74:$AO$74)+$B$74 -> #N/A | J4: Total covered years | M4: =Assms!B8 -> 23
A5: Annual premium for death claims | C5: =(C3/C4) -> #N/A | E5: =(E3/E4) -> #N/A | G5: =(G3/G4) -> #N/A | J5: Issue age: | M5: =age -> 0
A6: Grossed up for ongoing expenses | C6: =C5/(1-Assms!$C$19) -> #N/A | E6: =E5/(1-Assms!$C$19) -> #N/A | G6: =G5/(1-Assms!$C$19) -> #N/A | O6: Annual rate | P6: 0.06
A7: Total FY expenses & PV DAC tax | C7: =Assms!$C$14+C33 -> #N/A | E7: =Assms!$C$14+E33 -> #N/A | G7: =Assms!$C$14+G33 -> #N/A | O7: Int rate: | P7: =(1+Assms!K12)^(1/12)-1 -> 0.0048675506
A8: Premium for FY expenses & DAC tax I | C8: =C6*C7/C4 -> #N/A | E8: =E6*E7/E4 -> #N/A | G8: =G6*G7/G4 -> #N/A
A9: Premium for FY expenses & DAC tax II | C9: =C8*C7/C4 -> #N/A | E9: =E8*E7/E4 -> #N/A | G9: =G8*G7/G4 -> #N/A | K9: Pre-final | L9: Alt 1 | M9: Alt 2 | N9: Alt 3 | O9: Month | P9: =NPV(P7,P11:P21)+P10 -> 1752.9859
A10: Premium for FY expenses & DAC tax III | C10: =C9*C7/C4 -> #N/A | E10: =E9*E7/E4 -> #N/A | G10: =G9*G7/G4 -> #N/A | J10: Premium | K10: =I30 -> #N/A | L10: =K10*(1+K16) -> #N/A | M10: =L10*(1+L16) -> #N/A | N10: =M10*(1+M16) -> #N/A | O10: 0 | P10: 150.015
A11: Premium for FY expenses & DAC tax IV | C11: =C10*C7/C4 -> #N/A | E11: =E10*E7/E4 -> #N/A | G11: =G10*G7/G4 -> #N/A | J11: PV premium | K11: =NPV(Assms!K14,C95:AO95)+B95 -> #N/A | L11: ='Alt1'!E1 -> #N/A | M11: ='Alt2'!E1 -> #N/A | N11: ='Alt3'!E1 -> #N/A | O11: 1 | P11: =$P$10 -> 150.015
A12: Premium for FY expenses & DAC tax V | C12: =C11*C7/C4 -> #N/A | E12: =E11*E7/E4 -> #N/A | G12: =G11*G7/G4 -> #N/A | J12: PV book pft | K12: =NPV(Assms!K14,B106:AO106) -> #N/A | L12: ='Alt1'!E2 -> #N/A | M12: ='Alt2'!E2 -> #N/A | N12: ='Alt3'!E2 -> #N/A | O12: 2 | P12: =$P$10 -> 150.015
A13: Annual premium (Prelim 2) | C13: =C6+SUM(C8:C12) -> #N/A | E13: =E6+SUM(E8:E12) -> #N/A | G13: =G6+SUM(G8:G12) -> #N/A | J13: Margin | K13: =K12/K11 -> #N/A | L13: ='Alt1'!E3 -> #N/A | M13: ='Alt2'!E3 -> #N/A | N13: ='Alt3'!E3 -> #N/A | O13: 3 | P13: =$P$10 -> 150.015
A14: Premium grossed up for margin | C14: =C13/(1-Assms!$K$18) -> #N/A | E14: =E13/(1-Assms!$K$18) -> #N/A | G14: =G13/(1-Assms!$K$18) -> #N/A | J14: Target | K14: =Assms!K16 -> 0.06 | L14: =Assms!K16 -> 0.06 | M14: =Assms!K16 -> 0.06 | O14: 4 | P14: =$P$10 -> 150.015
A15: Savings for FY comp on pol fee I | C15: =Assms!$C$31*Assms!$C$12 -> 127.5 | E15: =Assms!$C$31*Assms!$C$12 -> 127.5 | G15: =Assms!$C$31*Assms!$C$12 -> 127.5 | J15: Variance | K15: =K13-K14 -> #N/A | L15: =L13-L14 -> #N/A | M15: =M13-M14 -> #N/A | O15: 5 | P15: =$P$10 -> 150.015
A16: Premium for FY expenses & DAC tax II | C16: =C15/C4 -> #N/A | E16: =E15/E4 -> #N/A | G16: =G15/G4 -> #N/A | J16: Adjustment | K16: =-K15*(1+Assms!$K$18)/(1-Assms!$K$13) -> #N/A | L16: =-L15*(1+Assms!$K$18)/(1-Assms!$K$13) -> #N/A | M16: =-M15*(1+Assms!$K$18)/(1-Assms!$K$13) -> #N/A | O16: 6 | P16: =$P$10 -> 150.015
A17: Premium for FY expenses & DAC tax III | C17: =C16/C4 -> #N/A | E17: =E16/E4 -> #N/A | G17: =G16/G4 -> #N/A | O17: 7 | P17: =$P$10 -> 150.015
A18: Premium for FY expenses & DAC tax IV | C18: =C17/C4 -> #N/A | E18: =E17/E4 -> #N/A | G18: =G17/G4 -> #N/A | J18: Other metrics only for viewing; not used | O18: 8 | P18: =$P$10 -> 150.015
A19: Premium reduction grossed up | C19: =-SUM(C16:C18)/(1-Assms!$K$18) -> #N/A | E19: =-SUM(E16:E18)/(1-Assms!$K$18) -> #N/A | G19: =-SUM(G16:G18)/(1-Assms!$K$18) -> #N/A | L19: Stat strain | M19: ='Alt3'!E5 -> #N/A | O19: 9 | P19: =$P$10 -> 150.015
A20: Premium for costs related to gross up I | C20: =(C14-C13)*(Assms!$C$14+C$33)/C4 -> #N/A | E20: =(E14-E13)*(Assms!$C$14+C$33)/E4 -> #N/A | G20: =(G14-G13)*(Assms!$C$14+E$33)/G4 -> #N/A | L20: IRR with RBC | M20: ='Alt3'!E4 -> #VALUE! | O20: 10 | P20: =$P$10 -> 150.015
A21: Premium for costs related to gross up II | C21: =C20*(Assms!$C$14+$B$33)/C4 -> #N/A | E21: =E20*(Assms!$C$14+$B$33)/E4 -> #N/A | G21: =G20*(Assms!$C$14+$B$33)/G4 -> #N/A | O21: 11 | P21: =$P$10 -> 150.015
A22: Premium for costs related to gross up III | C22: =C21*(Assms!$C$14+$B$33)/C4 -> #N/A | E22: =E21*(Assms!$C$14+$B$33)/E4 -> #N/A | G22: =G21*(Assms!$C$14+$B$33)/G4 -> #N/A
A23: Premium for costs related to gross up IV | C23: =C22*(Assms!$C$14+$B$33)/C4 -> #N/A | E23: =E22*(Assms!$C$14+$B$33)/E4 -> #N/A | G23: =G22*(Assms!$C$14+$B$33)/G4 -> #N/A | J23: Final monthly premium quote: | M23: =N10*P24/12 -> #N/A | O23: Annual/12 | P23: 146.08
A24: Pre fixed cost Annual Premium | C24: =C14+C19+SUM(C20:C23) -> #N/A | E24: =E14+E19+SUM(E20:E23) -> #N/A | G24: =G14+G19+SUM(G20:G23) -> #N/A | O24: Conversion | P24: =P21/P23 -> 1.0269373
A25: Premium for per policy expenses | C25: =(NPV(Assms!$K$14,$C$53:$AO$53)+$B$53)/C4 -> #N/A | E25: =(NPV(Assms!$K$14,$C$66:$AO$66)+$B$66)/E4 -> #N/A | G25: =(NPV(Assms!$K$14,$C$79:$AO$79)+$B$79)/G4 -> #N/A
A26: Premium for extra comp & DAC tax | C26: =(C25*Assms!$C$14)*(1+C$33+Assms!$C$19)/C$4 -> #N/A | E26: =(E25*Assms!$C$14)*(1+C$33+Assms!$C$19)/E$4 -> #N/A | G26: =(G25*Assms!$C$14)*(1+E$33+Assms!$C$19)/G$4 -> #N/A
A27: Premium for extra comp & DAC tax II | C27: =(C26*Assms!$C$14)*(1+C$33+Assms!$C$19)/C$4 -> #N/A | E27: =(E26*Assms!$C$14)*(1+C$33+Assms!$C$19)/E$4 -> #N/A | G27: =(G26*Assms!$C$14)*(1+E$33+Assms!$C$19)/G$4 -> #N/A
A28: Premium for extra comp & DAC tax III | C28: =(C27*Assms!$C$14)*(1+C$33+Assms!$C$19)/C$4 -> #N/A | E28: =(E27*Assms!$C$14)*(1+C$33+Assms!$C$19)/E$4 -> #N/A | G28: =(G27*Assms!$C$14)*(1+E$33+Assms!$C$19)/G$4 -> #N/A | H28: Final "Base" | I28: Initial test | J28: check: is the benefit zero in all years so as to produce a bogus premium (e.g., pol expenses)?
A29: Premium for extra comp & DAC tax IV | C29: =(C28*Assms!$C$14)*(1+C$33+Assms!$C$19)/C$4 -> #N/A | E29: =(E28*Assms!$C$14)*(1+C$33+Assms!$C$19)/E$4 -> #N/A | G29: =(G28*Assms!$C$14)*(1+E$33+Assms!$C$19)/G$4 -> #N/A | H29: Premium | I29: Premium
A30: Total annual premium | C30: =SUM(C24:C29) -> #N/A | E30: =SUM(E24:E29) -> #N/A | G30: =SUM(G24:G29) -> #N/A | H30: =G30 -> #N/A | I30: =IF(J30="Yes",0,G30) -> #N/A | J30: =IF(SUM(Assms!B6:AO6)=0,"Yes","No") -> No
E31: =E30/C30-1 -> #N/A | G31: =G30/E30-1 -> #N/A
A33: Cost of DAC tax (PV CFs as % initial premium) | C33: =DACtax!K3 -> #N/A | E33: =C33 -> #N/A | G33: =C33 -> #N/A
A35: Policy Year | B35: 1 | C35: =B35+1 -> 2 | D35: =C35+1 -> 3 | E35: =D35+1 -> 4 | F35: =E35+1 -> 5 | G35: =F35+1 -> 6 | H35: =G35+1 -> 7 | I35: =H35+1 -> 8 | J35: =I35+1 -> 9 | ... AO35: =AN35+1 -> 40
A36: Age of insured | B36: =age -> 0 | C36: =B36+1 -> 1 | D36: =C36+1 -> 2 | E36: =D36+1 -> 3 | F36: =E36+1 -> 4 | G36: =F36+1 -> 5 | H36: =G36+1 -> 6 | I36: =H36+1 -> 7 | J36: =I36+1 -> 8 | ... AO36: =AN36+1 -> 39
A37: Coverage active? | B37: 1 | C37: =IF(C39>0,1,0) -> 1 | D37: =IF(D39>0,1,0) -> 1 | E37: =IF(E39>0,1,0) -> 1 | F37: =IF(F39>0,1,0) -> 1 | G37: =IF(G39>0,1,0) -> 1 | H37: =IF(H39>0,1,0) -> 1 | I37: =IF(I39>0,1,0) -> 1 | J37: =IF(J39>0,1,0) -> 1 | ... AO37: =IF(AO39>0,1,0) -> 0
A38: Inflation factor (cumulative since issue) | B38: 1 | C38: =B38*(1+Assms!C23) -> 1.02 | D38: =C38*(1+Assms!C23) -> 1.0404 | E38: =D38*(1+Assms!C23) -> 1.061208 | F38: =E38*(1+Assms!C23) -> 1.0824322 | G38: =F38*(1+Assms!C23) -> 1.1040808 | H38: =G38*(1+Assms!C23) -> 1.1261624 | I38: =H38*(1+Assms!C23) -> 1.1486857 | J38: =I38*(1+Assms!C23) -> 1.1716594 | K38: =J38*(1+Assms!C23) -> 1.1950926 | L38: =K38*(1+Assms!C23) -> 1.2189944 | M38: =L38*(1+Assms!C23) -> 1.2433743 | N38: =M38*(1+Assms!C23) -> 1.2682418 | O38: =N38*(1+Assms!C23) -> 1.2936066 | P38: =O38*(1+Assms!C23) -> 1.3194788 | Q38: =P38*(1+Assms!C23) -> 1.3458683 | R38: =Q38*(1+Assms!C23) -> 1.3727857 | S38: =R38*(1+Assms!C23) -> 1.4002414 | T38: =S38*(1+Assms!C23) -> 1.4282462 | U38: =T38*(1+Assms!C23) -> 1.4568112 | V38: =U38*(1+Assms!C23) -> 1.4859474 | W38: =V38*(1+Assms!C23) -> 1.5156663 | X38: =W38*(1+Assms!C23) -> 1.5459797 | Y38: =X38*(1+Assms!C23) -> 1.5768993 | Z38: =Y38*(1+Assms!C23) -> 1.6084372 | AA38: =Z38*(1+Assms!C23) -> 1.640606 | AB38: =AA38*(1+Assms!C23) -> 1.6734181 | AC38: =AB38*(1+Assms!C23) -> 1.7068865 | AD38: =AC38*(1+Assms!C23) -> 1.7410242 | AE38: =AD38*(1+Assms!C23) -> 1.7758447 | AF38: =AE38*(1+Assms!C23) -> 1.8113616 | AG38: =AF38*(1+Assms!C23) -> 1.8475888 | AH38: =AG38*(1+Assms!C23) -> 1.8845406 | AI38: =AH38*(1+Assms!C23) -> 1.9222314 | AJ38: =AI38*(1+Assms!C23) -> 1.960676 | AK38: =AJ38*(1+Assms!C23) -> 1.9998896 | AL38: =AK38*(1+Assms!C23) -> 2.0398873 | AM38: =AL38*(1+Assms!C23) -> 2.0806851 | AN38: =AM38*(1+Assms!C23) -> 2.1222988 | AO38: =AN38*(1+Assms!C23) -> 2.1647448
A39: Death benefit | B39: =Assms!B6 -> 842000 | C39: =Assms!C6 -> 837000 | D39: =Assms!D6 -> 830000 | E39: =Assms!E6 -> 821000 | F39: =Assms!F6 -> 811000 | G39: =Assms!G6 -> 798000 | H39: =Assms!H6 -> 784000 | I39: =Assms!I6 -> 767000 | ... AO39: =Assms!AO6 -> 0
A40: Mortality rate before auto slippage | B40: =PriceQx!$B3/1000 -> #N/A | C40: =PriceQx!$B4/1000 -> #N/A | D40: =PriceQx!$B5/1000 -> #N/A | E40: =PriceQx!$B6/1000 -> #N/A | F40: =PriceQx!$B7/1000 -> #N/A | G40: =PriceQx!$B8/1000 -> #N/A | H40: =PriceQx!$B9/1000 -> #N/A | I40: =PriceQx!$B10/1000 -> #N/A | J40: =PriceQx!$B11/1000 -> #N/A | K40: =PriceQx!$B12/1000 -> #N/A | L40: =PriceQx!$B13/1000 -> #N/A | M40: =PriceQx!$B14/1000 -> #N/A | N40: =PriceQx!$B15/1000 -> #N/A | O40: =PriceQx!$B16/1000 -> #N/A | P40: =PriceQx!$B17/1000 -> #N/A | Q40: =PriceQx!$B18/1000 -> #N/A | R40: =PriceQx!$B19/1000 -> #N/A | S40: =PriceQx!$B20/1000 -> #N/A | T40: =PriceQx!$B21/1000 -> #N/A | U40: =PriceQx!$B22/1000 -> #N/A | V40: =PriceQx!$B23/1000 -> #N/A | W40: =PriceQx!$B24/1000 -> #N/A | X40: =PriceQx!$B25/1000 -> #N/A | Y40: =PriceQx!$B24/1000 -> #N/A | Z40: =PriceQx!$B27/1000 -> #N/A | AA40: =PriceQx!$B28/1000 -> #N/A | AB40: =PriceQx!$B29/1000 -> #N/A | AC40: =PriceQx!$B30/1000 -> #N/A | AD40: =PriceQx!$B31/1000 -> #N/A | AE40: =PriceQx!$B32/1000 -> #N/A | AF40: =PriceQx!$B33/1000 -> #N/A | AG40: =PriceQx!$B34/1000 -> #N/A | AH40: =PriceQx!$B35/1000 -> #N/A | AI40: =PriceQx!$B36/1000 -> #N/A | AJ40: =PriceQx!$B37/1000 -> #N/A | AK40: =PriceQx!$B38/1000 -> #N/A | AL40: =PriceQx!$B39/1000 -> #N/A | AM40: =PriceQx!$B40/1000 -> #N/A | AN40: =PriceQx!$B41/1000 -> #N/A | AO40: =PriceQx!$B42/1000 -> #N/A
A41: Mortality improvement since issue | B41: 1 | C41: =B41*(1-Assms!$K$31) -> 0.99 | D41: =C41*(1-Assms!$K$31) -> 0.9801 | E41: =D41*(1-Assms!$K$31) -> 0.970299 | F41: =E41*(1-Assms!$K$31) -> 0.96059601 | G41: =F41*(1-Assms!$K$31) -> 0.95099005 | H41: =G41*(1-Assms!$K$31) -> 0.94148015 | I41: =H41*(1-Assms!$K$31) -> 0.93206535 | J41: =I41*(1-Assms!$K$31) -> 0.92274469 | ... AO41: =AN41*(1-Assms!$K$31) -> 0.67572905
A42: Final mortality rate with auto UW slippage | B42: =B40*(1+Assms!$G$16)*B41 -> #N/A | C42: =C40*(1+Assms!$G$16)*C41 -> #N/A | D42: =D40*(1+Assms!$G$16)*D41 -> #N/A | E42: =E40*(1+Assms!$G$16)*E41 -> #N/A | F42: =F40*(1+Assms!$G$16)*F41 -> #N/A | G42: =G40*(1+Assms!$G$16)*G41 -> #N/A | H42: =H40*(1+Assms!$G$16)*H41 -> #N/A | I42: =I40*(1+Assms!$G$16)*I41 -> #N/A | ... AO42: =AO40*(1+Assms!$G$16)*AO41 -> #N/A
...

Sheet Alt1
A1: Calculate IRR with Alt1 premium | B1: =Pricing!L10 -> #N/A | D1: PV premium | E1: =NPV(Assms!K14,C35:AO35)+B35 -> #N/A
D2: PV book pft | E2: =NPV(Assms!K14,B46:AO46) -> #N/A
A3: Last year of coverage requested (BOY age): | B3: =Pricing!M1 -> 0 | D3: Margin | E3: =E2/E1 -> #N/A
A4: Last year of custom design model (BOY age) | B4: =Pricing!M2 -> 22
A5: Last year of coverage priced/shown | B5: =Pricing!M3 -> 0
A7: Policy Year | B7: 1 | C7: =B7+1 -> 2 | D7: =C7+1 -> 3 | E7: =D7+1 -> 4 | F7: =E7+1 -> 5 | G7: =F7+1 -> 6 | H7: =G7+1 -> 7 | I7: =H7+1 -> 8 | J7: =I7+1 -> 9 | ... AO7: =AN7+1 -> 40
A8: Age of insured | B8: =Pricing!B36 -> 0 | C8: =Pricing!C36 -> 1 | D8: =Pricing!D36 -> 2 | E8: =Pricing!E36 -> 3 | F8: =Pricing!F36 -> 4 | G8: =Pricing!G36 -> 5 | H8: =Pricing!H36 -> 6 | I8: =Pricing!I36 -> 7 | ... AO8: =Pricing!AO36 -> 39
A9: Coverage active? | B9: =Pricing!B37 -> 1 | C9: =Pricing!C37 -> 1 | D9: =Pricing!D37 -> 1 | E9: =Pricing!E37 -> 1 | F9: =Pricing!F37 -> 1 | G9: =Pricing!G37 -> 1 | H9: =Pricing!H37 -> 1 | I9: =Pricing!I37 -> 1 | ... AO9: =Pricing!AO37 -> 0
A10: Inflation factor (cumulative since issue) | B10: 1 | C10: =B10*(1+Assms!C23) -> 1.02 | D10: =C10*(1+Assms!C23) -> 1.0404 | E10: =D10*(1+Assms!C23) -> 1.061208 | F10: =E10*(1+Assms!C23) -> 1.0824322 | G10: =F10*(1+Assms!C23) -> 1.1040808 | H10: =G10*(1+Assms!C23) -> 1.1261624 | I10: =H10*(1+Assms!C23) -> 1.1486857 | J10: =I10*(1+Assms!C23) -> 1.1716594 | K10: =J10*(1+Assms!C23) -> 1.1950926 | L10: =K10*(1+Assms!C23) -> 1.2189944 | M10: =L10*(1+Assms!C23) -> 1.2433743 | N10: =M10*(1+Assms!C23) -> 1.2682418 | O10: =N10*(1+Assms!C23) -> 1.2936066 | P10: =O10*(1+Assms!C23) -> 1.3194788 | Q10: =P10*(1+Assms!C23) -> 1.3458683 | R10: =Q10*(1+Assms!C23) -> 1.3727857 | S10: =R10*(1+Assms!C23) -> 1.4002414 | T10: =S10*(1+Assms!C23) -> 1.4282462 | U10: =T10*(1+Assms!C23) -> 1.4568112 | V10: =U10*(1+Assms!C23) -> 1.4859474 | W10: =V10*(1+Assms!C23) -> 1.5156663 | X10: =W10*(1+Assms!C23) -> 1.5459797 | Y10: =X10*(1+Assms!C23) -> 1.5768993 | Z10: =Y10*(1+Assms!C23) -> 1.6084372 | AA10: =Z10*(1+Assms!C23) -> 1.640606 | AB10: =AA10*(1+Assms!C23) -> 1.6734181 | AC10: =AB10*(1+Assms!C23) -> 1.7068865 | AD10: =AC10*(1+Assms!C23) -> 1.7410242 | AE10: =AD10*(1+Assms!C23) -> 1.7758447 | AF10: =AE10*(1+Assms!C23) -> 1.8113616 | AG10: =AF10*(1+Assms!C23) -> 1.8475888 | AH10: =AG10*(1+Assms!C23) -> 1.8845406 | AI10: =AH10*(1+Assms!C23) -> 1.9222314 | AJ10: =AI10*(1+Assms!C23) -> 1.960676 | AK10: =AJ10*(1+Assms!C23) -> 1.9998896 | AL10: =AK10*(1+Assms!C23) -> 2.0398873 | AM10: =AL10*(1+Assms!C23) -> 2.0806851 | AN10: =AM10*(1+Assms!C23) -> 2.1222988 | AO10: =AN10*(1+Assms!C23) -> 2.1647448
A11: Expected mortality rate | B11: =Pricing!B42 -> #N/A | C11: =Pricing!C42 -> #N/A | D11: =Pricing!D42 -> #N/A | E11: =Pricing!E42 -> #N/A | F11: =Pricing!F42 -> #N/A | G11: =Pricing!G42 -> #N/A | H11: =Pricing!H42 -> #N/A | I11: =Pricing!I42 -> #N/A | ... AO11: =Pricing!AO42 -> #N/A
A12: Lapse rate with excess | B12: =Pricing!B57 -> 0.04 | C12: =Pricing!C57 -> 0.05 | D12: =Pricing!D57 -> 0.05 | E12: =Pricing!E57 -> 0.04 | F12: =Pricing!F57 -> 0.04 | G12: =Pricing!G57 -> 0.04 | H12: =Pricing!H57 -> 0.03 | I12: =Pricing!I57 -> 0.03 | ... AO12: =Pricing!AO57 -> 0.02
A13: EOY survival rate before that yr's Qx and Lx | B13: 1 | C13: =B13*(1-B12-B11) -> #N/A | D13: =C13*(1-C12-C11) -> #N/A | E13: =D13*(1-D12-D11) -> #N/A | F13: =E13*(1-E12-E11) -> #N/A | G13: =F13*(1-F12-F11) -> #N/A | H13: =G13*(1-G12-G11) -> #N/A | I13: =H13*(1-H12-H11) -> #N/A | J13: =I13*(1-I12-I11) -> #N/A | ... AO13: =AN13*(1-AN12-AN11) -> #N/A
A14: Survival rate for coverage period | B14: =IF(B9=1,B13,0) -> 1 | C14: =IF(C9=1,C13,0) -> #N/A | D14: =IF(D9=1,D13,0) -> #N/A | E14: =IF(E9=1,E13,0) -> #N/A | F14: =IF(F9=1,F13,0) -> #N/A | G14: =IF(G9=1,G13,0) -> #N/A | H14: =IF(H9=1,H13,0) -> #N/A | I14: =IF(I9=1,I13,0) -> #N/A | ... AO14: =IF(AO9=1,AO13,0) -> 0
A16: Death benefit | B16: =Pricing!B39 -> 842000 | C16: =Pricing!C39 -> 837000 | D16: =Pricing!D39 -> 830000 | E16: =Pricing!E39 -> 821000 | F16: =Pricing!F39 -> 811000 | G16: =Pricing!G39 -> 798000 | H16: =Pricing!H39 -> 784000 | I16: =Pricing!I39 -> 767000 | ... AO16: =Pricing!AO39 -> 0
A17: Inforce death benefit (beg of year) | B17: =B16*B14 -> 842000 | C17: =C16*C14 -> #N/A | D17: =D16*D14 -> #N/A | E17: =E16*E14 -> #N/A | F17: =F16*F14 -> #N/A | G17: =G16*G14 -> #N/A | H17: =H16*H14 -> #N/A | I17: =I16*I14 -> #N/A | ... AO17: =AO16*AO14 -> 0
A18: Expected death claims (EOY before lapses) | B18: =B17*B11 -> #N/A | C18: =C17*C11 -> #N/A | D18: =D17*D11 -> #N/A | E18: =E17*E11 -> #N/A | F18: =F17*F11 -> #N/A | G18: =G17*G11 -> #N/A | H18: =H17*H11 -> #N/A | I18: =I17*I11 -> #N/A | ... AO18: =AO17*AO11 -> #N/A
A19: Inforce premium collected (beg of year) | B19: =$B$1*B14 -> #N/A | C19: =$B$1*C14 -> #N/A | D19: =$B$1*D14 -> #N/A | E19: =$B$1*E14 -> #N/A | F19: =$B$1*F14 -> #N/A | G19: =$B$1*G14 -> #N/A | H19: =$B$1*H14 -> #N/A | I19: =$B$1*I14 -> #N/A | ... AO19: =$B$1*AO14 -> #N/A
A20: Per Policy expenses | B20: =Assms!C21+Assms!C22 -> 150 | C20: =Assms!C22*C10*C14 -> #N/A | D20: =Assms!C22*D10*D14 -> #N/A | E20: =Assms!C22*E10*E14 -> #N/A | F20: =Assms!C22*F10*F14 -> #N/A | G20: =Assms!C22*G10*G14 -> #N/A | H20: =Assms!C22*H10*H14 -> #N/A | I20: =Assms!C22*I10*I14 -> #N/A | J20: =Assms!C22*J10*J14 -> #N/A | K20: =Assms!C22*K10*K14 -> #N/A | L20: =Assms!C22*L10*L14 -> #N/A | M20: =Assms!C22*M10*M14 -> #N/A | N20: =Assms!C22*N10*N14 -> #N/A | O20: =Assms!C22*O10*O14 -> #N/A | P20: =Assms!C22*P10*P14 -> #N/A | Q20: =Assms!C22*Q10*Q14 -> #N/A | R20: =Assms!C22*R10*R14 -> #N/A | S20: =Assms!C22*S10*S14 -> #N/A | T20: =Assms!C22*T10*T14 -> #N/A | U20: =Assms!C22*U10*U14 -> #N/A | V20: =Assms!C22*V10*V14 -> #N/A | W20: =Assms!C22*W10*W14 -> #N/A | X20: =Assms!C22*X10*X14 -> #N/A | Y20: =Assms!C22*Y10*Y14 -> 0 | Z20: =Assms!C22*Z10*Z14 -> 0 | AA20: =Assms!C22*AA10*AA14 -> 0 | AB20: =Assms!C22*AB10*AB14 -> 0 | AC20: =Assms!C22*AC10*AC14 -> 0 | AD20: =Assms!C22*AD10*AD14 -> 0 | AE20: =Assms!C22*AE10*AE14 -> 0 | AF20: =Assms!C22*AF10*AF14 -> 0 | AG20: =Assms!C22*AG10*AG14 -> 0 | AH20: =Assms!C22*AH10*AH14 -> 0 | AI20: =Assms!C22*AI10*AI14 -> 0 | AJ20: =Assms!C22*AJ10*AJ14 -> 0 | AK20: =Assms!C22*AK10*AK14 -> 0 | AL20: =Assms!C22*AL10*AL14 -> 0 | AM20: =Assms!C22*AM10*AM14 -> 0 | AN20: =Assms!C22*AN10*AN14 -> 0 | AO20: =Assms!C22*AO10*AO14 -> 0
A22: Profitability Calculation
A23: Inforce? | B23: =StatV!B12 -> 1 | C23: =StatV!C12 -> 1 | D23: =StatV!D12 -> 1 | E23: =StatV!E12 -> 1 | F23: =StatV!F12 -> 1 | G23: =StatV!G12 -> 1 | H23: =StatV!H12 -> 1 | I23: =StatV!I12 -> 1 | ... AO23: =StatV!AO12 -> 0
A24: Reserve per DB inforce | B24: =StatV!B203 -> #N/A | C24: =StatV!C203 -> #N/A | D24: =StatV!D203 -> #N/A | E24: =StatV!E203 -> #N/A | F24: =StatV!F203 -> #N/A | G24: =StatV!G203 -> #N/A | H24: =StatV!H203 -> #N/A | I24: =StatV!I203 -> #N/A | ... AO24: =StatV!AO203 -> #N/A
A25: Cash Value per DB inforce | B25: =CashValue!C39 -> #N/A | C25: =CashValue!D39 -> #N/A | D25: =CashValue!E39 -> #N/A | E25: =CashValue!F39 -> #N/A | F25: =CashValue!G39 -> #N/A | G25: =CashValue!H39 -> #N/A | H25: =CashValue!I39 -> #N/A | I25: =CashValue!J39 -> #N/A | ... AO25: =CashValue!AP39 -> #N/A
A26: Mortality rate | B26: =Pricing!B72 -> #N/A | C26: =Pricing!C72 -> #N/A | D26: =Pricing!D72 -> #N/A | E26: =Pricing!E72 -> #N/A | F26: =Pricing!F72 -> #N/A | G26: =Pricing!G72 -> #N/A | H26: =Pricing!H72 -> #N/A | I26: =Pricing!I72 -> #N/A | ... AO26: =Pricing!AO72 -> #N/A
A27: Lapse rate | B27: =Pricing!B69 -> 0.04 | C27: =Pricing!C69 -> 0.05 | D27: =Pricing!D69 -> 0.05 | E27: =Pricing!E69 -> 0.04 | F27: =Pricing!F69 -> 0.04 | G27: =Pricing!G69 -> 0.04 | H27: =Pricing!H69 -> 0.03 | I27: =Pricing!I69 -> 0.03 | ... AO27: =Pricing!AO69 -> 0.02
A28: tPx (beg yr) | B28: 1 | C28: =IF(C23=1,B28*(1-B26-B27),0) -> #N/A | D28: =IF(D23=1,C28*(1-C26-C27),0) -> #N/A | E28: =IF(E23=1,D28*(1-D26-D27),0) -> #N/A | F28: =IF(F23=1,E28*(1-E26-E27),0) -> #N/A | G28: =IF(G23=1,F28*(1-F26-F27),0) -> #N/A | H28: =IF(H23=1,G28*(1-G26-G27),0) -> #N/A | I28: =IF(I23=1,H28*(1-H26-H27),0) -> #N/A | J28: =IF(J23=1,I28*(1-I26-I27),0) -> #N/A | ... AO28: =IF(AO23=1,AN28*(1-AN26-AN27),0) -> 0
A29: Inforce DB (BOY) | B29: =Pricing!B39*B28 -> 842000 | C29: =Pricing!C39*C28 -> #N/A | D29: =Pricing!D39*D28 -> #N/A | E29: =Pricing!E39*E28 -> #N/A | F29: =Pricing!F39*F28 -> #N/A | G29: =Pricing!G39*G28 -> #N/A | H29: =Pricing!H39*H28 -> #N/A | I29: =Pricing!I39*I28 -> #N/A | ... AO29: =Pricing!AO39*AO28 -> 0
A30: Reserve inforce | B30: =B29*B24 -> #N/A | C30: =C29*C24 -> #N/A | D30: =D29*D24 -> #N/A | E30: =E29*E24 -> #N/A | F30: =F29*F24 -> #N/A | G30: =G29*G24 -> #N/A | H30: =H29*H24 -> #N/A | I30: =I29*I24 -> #N/A | ... AN30: =AN29*AN24 -> #N/A | AO30: 0
A31: CV inforce | B31: =B29*B25 -> #N/A | C31: =C29*C25 -> #N/A | D31: =D29*D25 -> #N/A | E31: =E29*E25 -> #N/A | F31: =F29*F25 -> #N/A | G31: =G29*G25 -> #N/A | H31: =H29*H25 -> #N/A | I31: =I29*I25 -> #N/A | ... AO31: =AO29*AO25 -> #N/A
A33: Stat book profit (customized policy)
A34: Policy Year | B34: 1 | C34: =B34+1 -> 2 | D34: =C34+1 -> 3 | E34: =D34+1 -> 4 | F34: =E34+1 -> 5 | G34: =F34+1 -> 6 | H34: =G34+1 -> 7 | I34: =H34+1 -> 8 | J34: =I34+1 -> 9 | ... AO34: =AN34+1 -> 40
A35: Premiums | B35: =$B$1*B28 -> #N/A | C35: =$B$1*C28 -> #N/A | D35: =$B$1*D28 -> #N/A | E35: =$B$1*E28 -> #N/A | F35: =$B$1*F28 -> #N/A | G35: =$B$1*G28 -> #N/A | H35: =$B$1*H28 -> #N/A | I35: =$B$1*I28 -> #N/A | ... AO35: =$B$1*AO28 -> #N/A
A36: Inv Inc reserves | B36: =Assms!$K$12*B30 -> #N/A | C36: =Assms!$K$12*C30 -> #N/A | D36: =Assms!$K$12*D30 -> #N/A | E36: =Assms!$K$12*E30 -> #N/A | F36: =Assms!$K$12*F30 -> #N/A | G36: =Assms!$K$12*G30 -> #N/A | H36: =Assms!$K$12*H30 -> #N/A | I36: =Assms!$K$12*I30 -> #N/A | ... AO36: =Assms!$K$12*AO30 -> 0
A37: Prem-based exp | B37: =(B35-B28*Assms!$C$31)*Assms!$C$12+(Assms!$C$13*B35) -> #N/A | C37: =(C35-C28*Assms!$C$31)*Assms!$C$17+(C35*(Assms!$C$16+Assms!$C$18)) -> #N/A | D37: =(D35-D28*Assms!$C$31)*Assms!$C$17+(D35*(Assms!$C$16+Assms!$C$18)) -> #N/A | E37: =(E35-E28*Assms!$C$31)*Assms!$C$17+(E35*(Assms!$C$16+Assms!$C$18)) -> #N/A | F37: =(F35-F28*Assms!$C$31)*Assms!$C$17+(F35*(Assms!$C$16+Assms!$C$18)) -> #N/A | G37: =(G35-G28*Assms!$C$31)*Assms!$C$17+(G35*(Assms!$C$16+Assms!$C$18)) -> #N/A | H37: =(H35-H28*Assms!$C$31)*Assms!$C$17+(H35*(Assms!$C$16+Assms!$C$18)) -> #N/A | I37: =(I35-I28*Assms!$C$31)*Assms!$C$17+(I35*(Assms!$C$16+Assms!$C$18)) -> #N/A | J37: =(J35-J28*Assms!$C$31)*Assms!$C$17+(J35*(Assms!$C$16+Assms!$C$18)) -> #N/A | ... AO37: =(AO35-AO28*Assms!$C$31)*Assms!$C$17+(AO35*(Assms!$C$16+Assms!$C$18)) -> #N/A
A38: Per policy Exp | B38: =Assms!C21+Assms!C22 -> 150 | C38: =IF(C29>0,Assms!$C$22*Pricing!C38*C28,0) -> #N/A | D38: =IF(D29>0,Assms!$C$22*Pricing!D38*D28,0) -> #N/A | E38: =IF(E29>0,Assms!$C$22*Pricing!E38*E28,0) -> #N/A | F38: =IF(F29>0,Assms!$C$22*Pricing!F38*F28,0) -> #N/A | G38: =IF(G29>0,Assms!$C$22*Pricing!G38*G28,0) -> #N/A | H38: =IF(H29>0,Assms!$C$22*Pricing!H38*H28,0) -> #N/A | I38: =IF(I29>0,Assms!$C$22*Pricing!I38*I28,0) -> #N/A | J38: =IF(J29>0,Assms!$C$22*Pricing!J38*J28,0) -> #N/A | ... AO38: =IF(AO29>0,Assms!$C$22*Pricing!AO38*AO28,0) -> 0
A39: Death claims | B39: =B29*B26 -> #N/A | C39: =C29*C26 -> #N/A | D39: =D29*D26 -> #N/A | E39: =E29*E26 -> #N/A | F39: =F29*F26 -> #N/A | G39: =G29*G26 -> #N/A | H39: =H29*H26 -> #N/A | I39: =I29*I26 -> #N/A | ... AO39: =AO29*AO26 -> #N/A
A40: Cash value/lapses | B40: =IF(B23=1,B29*B27*B25,"") -> #N/A | C40: =IF(C23=1,C29*C27*C25,"") -> #N/A | D40: =IF(D23=1,D29*D27*D25,"") -> #N/A | E40: =IF(E23=1,E29*E27*E25,"") -> #N/A | F40: =IF(F23=1,F29*F27*F25,"") -> #N/A | G40: =IF(G23=1,G29*G27*G25,"") -> #N/A | H40: =IF(H23=1,H29*H27*H25,"") -> #N/A | I40: =IF(I23=1,I29*I27*I25,"") -> #N/A | ... AO40: =IF(AO23=1,AO29*AO27*AO25,"")
A41: Change in resv | B41: =B30 -> #N/A | C41: =C30-B30 -> #N/A | D41: =D30-C30 -> #N/A | E41: =E30-D30 -> #N/A | F41: =F30-E30 -> #N/A | G41: =G30-F30 -> #N/A | H41: =H30-G30 -> #N/A | I41: =I30-H30 -> #N/A | J41: =J30-I30 -> #N/A | ... AO41: =AO30-AN30 -> #N/A
A43: Pre-tax stat book | B43: =(B35+B36)-SUM(B37:B41) -> #N/A | C43: =(C35+C36)-SUM(C37:C41) -> #N/A | D43: =(D35+D36)-SUM(D37:D41) -> #N/A | E43: =(E35+E36)-SUM(E37:E41) -> #N/A | F43: =(F35+F36)-SUM(F37:F41) -> #N/A | G43: =(G35+G36)-SUM(G37:G41) -> #N/A | H43: =(H35+H36)-SUM(H37:H41) -> #N/A | I43: =(I35+I36)-SUM(I37:I41) -> #N/A | ... AO43: =(AO35+AO36)-SUM(AO37:AO41) -> #N/A
A44: Income tax | B44: =B43*Assms!K13 -> #N/A | C44: =C43*Assms!K13 -> #N/A | D44: =D43*Assms!K13 -> #N/A | E44: =E43*Assms!K13 -> #N/A | F44: =F43*Assms!K13 -> #N/A | G44: =G43*Assms!K13 -> #N/A | H44: =H43*Assms!K13 -> #N/A | I44: =I43*Assms!K13 -> #N/A | J44: =J43*Assms!K13 -> #N/A | K44: =K43*Assms!K13 -> #N/A | L44: =L43*Assms!K13 -> #N/A | M44: =M43*Assms!K13 -> #N/A | N44: =N43*Assms!K13 -> #N/A | O44: =O43*Assms!K13 -> #N/A | P44: =P43*Assms!K13 -> #N/A | Q44: =Q43*Assms!K13 -> #N/A | R44: =R43*Assms!K13 -> #N/A | S44: =S43*Assms!K13 -> #N/A | T44: =T43*Assms!K13 -> #N/A | U44: =U43*Assms!K13 -> #N/A | V44: =V43*Assms!K13 -> #N/A | W44: =W43*Assms!K13 -> #N/A | X44: =X43*Assms!K13 -> #N/A | Y44: =Y43*Assms!K13 -> #N/A | Z44: =Z43*Assms!K13 -> #N/A | AA44: =AA43*Assms!K13 -> #N/A | AB44: =AB43*Assms!K13 -> #N/A | AC44: =AC43*Assms!K13 -> #N/A | AD44: =AD43*Assms!K13 -> #N/A | AE44: =AE43*Assms!K13 -> #N/A | AF44: =AF43*Assms!K13 -> #N/A | AG44: =AG43*Assms!K13 -> #N/A | AH44: =AH43*Assms!K13 -> #N/A | AI44: =AI43*Assms!K13 -> #N/A | AJ44: =AJ43*Assms!K13 -> #N/A | AK44: =AK43*Assms!K13 -> #N/A | AL44: =AL43*Assms!K13 -> #N/A | AM44: =AM43*Assms!K13 -> #N/A | AN44: =AN43*Assms!K13 -> #N/A | AO44: =AO43*Assms!K13 -> #N/A
A45: DAC tax payments | B45: =Pricing!B105*'Alt1'!$B$1/Pricing!$K$10 -> #N/A | C45: =Pricing!C105*'Alt1'!$B$1/Pricing!$K$10 -> #N/A | D45: =Pricing!D105*'Alt1'!$B$1/Pricing!$K$10 -> #N/A | E45: =Pricing!E105*'Alt1'!$B$1/Pricing!$K$10 -> #N/A | F45: =Pricing!F105*'Alt1'!$B$1/Pricing!$K$10 -> #N/A | G45: =Pricing!G105*'Alt1'!$B$1/Pricing!$K$10 -> #N/A | H45: =Pricing!H105*'Alt1'!$B$1/Pricing!$K$10 -> #N/A | I45: =Pricing!I105*'Alt1'!$B$1/Pricing!$K$10 -> #N/A | ... AO45: =Pricing!AO105*'Alt1'!$B$1/Pricing!$K$10 -> #N/A
...

Sheet Alt2
A1: Calculate IRR with Alt2 premium | B1: =Pricing!M10 -> #N/A | D1: PV premium | E1: =NPV(Assms!K14,C35:AO35)+B35 -> #N/A
D2: PV book pft | E2: =NPV(Assms!K14,B46:AO46) -> #N/A
A3: Last year of coverage requested (BOY age): | B3: =Pricing!M1 -> 0 | D3: Margin | E3: =E2/E1 -> #N/A
A4: Last year of custom design model (BOY age) | B4: =Pricing!M2 -> 22
A5: Last year of coverage priced/shown | B5: =Pricing!M3 -> 0
A7: Policy Year | B7: 1 | C7: =B7+1 -> 2 | D7: =C7+1 -> 3 | E7: =D7+1 -> 4 | F7: =E7+1 -> 5 | G7: =F7+1 -> 6 | H7: =G7+1 -> 7 | I7: =H7+1 -> 8 | J7: =I7+1 -> 9 | ... AO7: =AN7+1 -> 40
A8: Age of insured | B8: =Pricing!B36 -> 0 | C8: =Pricing!C36 -> 1 | D8: =Pricing!D36 -> 2 | E8: =Pricing!E36 -> 3 | F8: =Pricing!F36 -> 4 | G8: =Pricing!G36 -> 5 | H8: =Pricing!H36 -> 6 | I8: =Pricing!I36 -> 7 | ... AO8: =Pricing!AO36 -> 39
A9: Coverage active? | B9: =Pricing!B37 -> 1 | C9: =Pricing!C37 -> 1 | D9: =Pricing!D37 -> 1 | E9: =Pricing!E37 -> 1 | F9: =Pricing!F37 -> 1 | G9: =Pricing!G37 -> 1 | H9: =Pricing!H37 -> 1 | I9: =Pricing!I37 -> 1 | ... AO9: =Pricing!AO37 -> 0
A10: Inflation factor (cumulative since issue) | B10: 1 | C10: =B10*(1+Assms!C23) -> 1.02 | D10: =C10*(1+Assms!C23) -> 1.0404 | E10: =D10*(1+Assms!C23) -> 1.061208 | F10: =E10*(1+Assms!C23) -> 1.0824322 | G10: =F10*(1+Assms!C23) -> 1.1040808 | H10: =G10*(1+Assms!C23) -> 1.1261624 | I10: =H10*(1+Assms!C23) -> 1.1486857 | J10: =I10*(1+Assms!C23) -> 1.1716594 | K10: =J10*(1+Assms!C23) -> 1.1950926 | L10: =K10*(1+Assms!C23) -> 1.2189944 | M10: =L10*(1+Assms!C23) -> 1.2433743 | N10: =M10*(1+Assms!C23) -> 1.2682418 | O10: =N10*(1+Assms!C23) -> 1.2936066 | P10: =O10*(1+Assms!C23) -> 1.3194788 | Q10: =P10*(1+Assms!C23) -> 1.3458683 | R10: =Q10*(1+Assms!C23) -> 1.3727857 | S10: =R10*(1+Assms!C23) -> 1.4002414 | T10: =S10*(1+Assms!C23) -> 1.4282462 | U10: =T10*(1+Assms!C23) -> 1.4568112 | V10: =U10*(1+Assms!C23) -> 1.4859474 | W10: =V10*(1+Assms!C23) -> 1.5156663 | X10: =W10*(1+Assms!C23) -> 1.5459797 | Y10: =X10*(1+Assms!C23) -> 1.5768993 | Z10: =Y10*(1+Assms!C23) -> 1.6084372 | AA10: =Z10*(1+Assms!C23) -> 1.640606 | AB10: =AA10*(1+Assms!C23) -> 1.6734181 | AC10: =AB10*(1+Assms!C23) -> 1.7068865 | AD10: =AC10*(1+Assms!C23) -> 1.7410242 | AE10: =AD10*(1+Assms!C23) -> 1.7758447 | AF10: =AE10*(1+Assms!C23) -> 1.8113616 | AG10: =AF10*(1+Assms!C23) -> 1.8475888 | AH10: =AG10*(1+Assms!C23) -> 1.8845406 | AI10: =AH10*(1+Assms!C23) -> 1.9222314 | AJ10: =AI10*(1+Assms!C23) -> 1.960676 | AK10: =AJ10*(1+Assms!C23) -> 1.9998896 | AL10: =AK10*(1+Assms!C23) -> 2.0398873 | AM10: =AL10*(1+Assms!C23) -> 2.0806851 | AN10: =AM10*(1+Assms!C23) -> 2.1222988 | AO10: =AN10*(1+Assms!C23) -> 2.1647448
A11: Expected mortality rate | B11: =Pricing!B42 -> #N/A | C11: =Pricing!C42 -> #N/A | D11: =Pricing!D42 -> #N/A | E11: =Pricing!E42 -> #N/A | F11: =Pricing!F42 -> #N/A | G11: =Pricing!G42 -> #N/A | H11: =Pricing!H42 -> #N/A | I11: =Pricing!I42 -> #N/A | ... AO11: =Pricing!AO42 -> #N/A
A12: Lapse rate with excess | B12: =Pricing!B59 -> 0.04 | C12: =Pricing!C59 -> 0.05 | D12: =Pricing!D59 -> 0.05 | E12: =Pricing!E59 -> 0.04 | F12: =Pricing!F59 -> 0.04 | G12: =Pricing!G59 -> 0.04 | H12: =Pricing!H59 -> 0.03 | I12: =Pricing!I59 -> 0.03 | ... AO12: =Pricing!AO59 -> 0.02
A13: EOY survival rate before that yr's Qx and Lx | B13: 1 | C13: =B13*(1-B12-B11) -> #N/A | D13: =C13*(1-C12-C11) -> #N/A | E13: =D13*(1-D12-D11) -> #N/A | F13: =E13*(1-E12-E11) -> #N/A | G13: =F13*(1-F12-F11) -> #N/A | H13: =G13*(1-G12-G11) -> #N/A | I13: =H13*(1-H12-H11) -> #N/A | J13: =I13*(1-I12-I11) -> #N/A | ... AO13: =AN13*(1-AN12-AN11) -> #N/A
A14: Survival rate for coverage period | B14: =IF(B9=1,B13,0) -> 1 | C14: =IF(C9=1,C13,0) -> #N/A | D14: =IF(D9=1,D13,0) -> #N/A | E14: =IF(E9=1,E13,0) -> #N/A | F14: =IF(F9=1,F13,0) -> #N/A | G14: =IF(G9=1,G13,0) -> #N/A | H14: =IF(H9=1,H13,0) -> #N/A | I14: =IF(I9=1,I13,0) -> #N/A | ... AO14: =IF(AO9=1,AO13,0) -> 0
A16: Death benefit | B16: =Pricing!B39 -> 842000 | C16: =Pricing!C39 -> 837000 | D16: =Pricing!D39 -> 830000 | E16: =Pricing!E39 -> 821000 | F16: =Pricing!F39 -> 811000 | G16: =Pricing!G39 -> 798000 | H16: =Pricing!H39 -> 784000 | I16: =Pricing!I39 -> 767000 | ... AO16: =Pricing!AO39 -> 0
A17: Inforce death benefit (beg of year) | B17: =B16*B14 -> 842000 | C17: =C16*C14 -> #N/A | D17: =D16*D14 -> #N/A | E17: =E16*E14 -> #N/A | F17: =F16*F14 -> #N/A | G17: =G16*G14 -> #N/A | H17: =H16*H14 -> #N/A | I17: =I16*I14 -> #N/A | ... AO17: =AO16*AO14 -> 0
A18: Expected death claims (EOY before lapses) | B18: =B17*B11 -> #N/A | C18: =C17*C11 -> #N/A | D18: =D17*D11 -> #N/A | E18: =E17*E11 -> #N/A | F18: =F17*F11 -> #N/A | G18: =G17*G11 -> #N/A | H18: =H17*H11 -> #N/A | I18: =I17*I11 -> #N/A | ... AO18: =AO17*AO11 -> #N/A
A19: Inforce premium collected (beg of year) | B19: =$B$1*B14 -> #N/A | C19: =$B$1*C14 -> #N/A | D19: =$B$1*D14 -> #N/A | E19: =$B$1*E14 -> #N/A | F19: =$B$1*F14 -> #N/A | G19: =$B$1*G14 -> #N/A | H19: =$B$1*H14 -> #N/A | I19: =$B$1*I14 -> #N/A | ... AO19: =$B$1*AO14 -> #N/A
A20: Per Policy expenses | B20: =Assms!C21+Assms!C22 -> 150 | C20: =Assms!C22*C10*C14 -> #N/A | D20: =Assms!C22*D10*D14 -> #N/A | E20: =Assms!C22*E10*E14 -> #N/A | F20: =Assms!C22*F10*F14 -> #N/A | G20: =Assms!C22*G10*G14 -> #N/A | H20: =Assms!C22*H10*H14 -> #N/A | I20: =Assms!C22*I10*I14 -> #N/A | J20: =Assms!C22*J10*J14 -> #N/A | K20: =Assms!C22*K10*K14 -> #N/A | L20: =Assms!C22*L10*L14 -> #N/A | M20: =Assms!C22*M10*M14 -> #N/A | N20: =Assms!C22*N10*N14 -> #N/A | O20: =Assms!C22*O10*O14 -> #N/A | P20: =Assms!C22*P10*P14 -> #N/A | Q20: =Assms!C22*Q10*Q14 -> #N/A | R20: =Assms!C22*R10*R14 -> #N/A | S20: =Assms!C22*S10*S14 -> #N/A | T20: =Assms!C22*T10*T14 -> #N/A | U20: =Assms!C22*U10*U14 -> #N/A | V20: =Assms!C22*V10*V14 -> #N/A | W20: =Assms!C22*W10*W14 -> #N/A | X20: =Assms!C22*X10*X14 -> #N/A | Y20: =Assms!C22*Y10*Y14 -> 0 | Z20: =Assms!C22*Z10*Z14 -> 0 | AA20: =Assms!C22*AA10*AA14 -> 0 | AB20: =Assms!C22*AB10*AB14 -> 0 | AC20: =Assms!C22*AC10*AC14 -> 0 | AD20: =Assms!C22*AD10*AD14 -> 0 | AE20: =Assms!C22*AE10*AE14 -> 0 | AF20: =Assms!C22*AF10*AF14 -> 0 | AG20: =Assms!C22*AG10*AG14 -> 0 | AH20: =Assms!C22*AH10*AH14 -> 0 | AI20: =Assms!C22*AI10*AI14 -> 0 | AJ20: =Assms!C22*AJ10*AJ14 -> 0 | AK20: =Assms!C22*AK10*AK14 -> 0 | AL20: =Assms!C22*AL10*AL14 -> 0 | AM20: =Assms!C22*AM10*AM14 -> 0 | AN20: =Assms!C22*AN10*AN14 -> 0 | AO20: =Assms!C22*AO10*AO14 -> 0
A22: Profitability Calculation
A23: Inforce? | B23: =StatV!B12 -> 1 | C23: =StatV!C12 -> 1 | D23: =StatV!D12 -> 1 | E23: =StatV!E12 -> 1 | F23: =StatV!F12 -> 1 | G23: =StatV!G12 -> 1 | H23: =StatV!H12 -> 1 | I23: =StatV!I12 -> 1 | ... AO23: =StatV!AO12 -> 0
A24: Reserve per DB inforce | B24: =StatV!B203 -> #N/A | C24: =StatV!C203 -> #N/A | D24: =StatV!D203 -> #N/A | E24: =StatV!E203 -> #N/A | F24: =StatV!F203 -> #N/A | G24: =StatV!G203 -> #N/A | H24: =StatV!H203 -> #N/A | I24: =StatV!I203 -> #N/A | ... AO24: =StatV!AO203 -> #N/A
A25: Cash Value per DB inforce | B25: =CashValue!C39 -> #N/A | C25: =CashValue!D39 -> #N/A | D25: =CashValue!E39 -> #N/A | E25: =CashValue!F39 -> #N/A | F25: =CashValue!G39 -> #N/A | G25: =CashValue!H39 -> #N/A | H25: =CashValue!I39 -> #N/A | I25: =CashValue!J39 -> #N/A | ... AO25: =CashValue!AP39 -> #N/A
A26: Mortality rate | B26: =Pricing!B72 -> #N/A | C26: =Pricing!C72 -> #N/A | D26: =Pricing!D72 -> #N/A | E26: =Pricing!E72 -> #N/A | F26: =Pricing!F72 -> #N/A | G26: =Pricing!G72 -> #N/A | H26: =Pricing!H72 -> #N/A | I26: =Pricing!I72 -> #N/A | ... AO26: =Pricing!AO72 -> #N/A
A27: Lapse rate | B27: =Pricing!B69 -> 0.04 | C27: =Pricing!C69 -> 0.05 | D27: =Pricing!D69 -> 0.05 | E27: =Pricing!E69 -> 0.04 | F27: =Pricing!F69 -> 0.04 | G27: =Pricing!G69 -> 0.04 | H27: =Pricing!H69 -> 0.03 | I27: =Pricing!I69 -> 0.03 | ... AO27: =Pricing!AO69 -> 0.02
A28: tPx (beg yr) | B28: 1 | C28: =IF(C23=1,B28*(1-B26-B27),0) -> #N/A | D28: =IF(D23=1,C28*(1-C26-C27),0) -> #N/A | E28: =IF(E23=1,D28*(1-D26-D27),0) -> #N/A | F28: =IF(F23=1,E28*(1-E26-E27),0) -> #N/A | G28: =IF(G23=1,F28*(1-F26-F27),0) -> #N/A | H28: =IF(H23=1,G28*(1-G26-G27),0) -> #N/A | I28: =IF(I23=1,H28*(1-H26-H27),0) -> #N/A | J28: =IF(J23=1,I28*(1-I26-I27),0) -> #N/A | ... AO28: =IF(AO23=1,AN28*(1-AN26-AN27),0) -> 0
A29: Inforce DB (BOY) | B29: =Pricing!B39*B28 -> 842000 | C29: =Pricing!C39*C28 -> #N/A | D29: =Pricing!D39*D28 -> #N/A | E29: =Pricing!E39*E28 -> #N/A | F29: =Pricing!F39*F28 -> #N/A | G29: =Pricing!G39*G28 -> #N/A | H29: =Pricing!H39*H28 -> #N/A | I29: =Pricing!I39*I28 -> #N/A | ... AO29: =Pricing!AO39*AO28 -> 0
A30: Reserve inforce | B30: =B29*B24 -> #N/A | C30: =C29*C24 -> #N/A | D30: =D29*D24 -> #N/A | E30: =E29*E24 -> #N/A | F30: =F29*F24 -> #N/A | G30: =G29*G24 -> #N/A | H30: =H29*H24 -> #N/A | I30: =I29*I24 -> #N/A | ... AN30: =AN29*AN24 -> #N/A | AO30: 0
A31: CV inforce | B31: =B29*B25 -> #N/A | C31: =C29*C25 -> #N/A | D31: =D29*D25 -> #N/A | E31: =E29*E25 -> #N/A | F31: =F29*F25 -> #N/A | G31: =G29*G25 -> #N/A | H31: =H29*H25 -> #N/A | I31: =I29*I25 -> #N/A | ... AO31: =AO29*AO25 -> #N/A
A33: Stat book profit (customized policy)
A34: Policy Year | B34: 1 | C34: =B34+1 -> 2 | D34: =C34+1 -> 3 | E34: =D34+1 -> 4 | F34: =E34+1 -> 5 | G34: =F34+1 -> 6 | H34: =G34+1 -> 7 | I34: =H34+1 -> 8 | J34: =I34+1 -> 9 | ... AO34: =AN34+1 -> 40
A35: Premiums | B35: =$B$1*B28 -> #N/A | C35: =$B$1*C28 -> #N/A | D35: =$B$1*D28 -> #N/A | E35: =$B$1*E28 -> #N/A | F35: =$B$1*F28 -> #N/A | G35: =$B$1*G28 -> #N/A | H35: =$B$1*H28 -> #N/A | I35: =$B$1*I28 -> #N/A | ... AO35: =$B$1*AO28 -> #N/A
A36: Inv Inc reserves | B36: =Assms!$K$12*B30 -> #N/A | C36: =Assms!$K$12*C30 -> #N/A | D36: =Assms!$K$12*D30 -> #N/A | E36: =Assms!$K$12*E30 -> #N/A | F36: =Assms!$K$12*F30 -> #N/A | G36: =Assms!$K$12*G30 -> #N/A | H36: =Assms!$K$12*H30 -> #N/A | I36: =Assms!$K$12*I30 -> #N/A | ... AO36: =Assms!$K$12*AO30 -> 0
A37: Prem-based exp | B37: =(B35-B28*Assms!$C$31)*Assms!$C$12+(Assms!$C$13*B35) -> #N/A | C37: =(C35-C28*Assms!$C$31)*Assms!$C$17+(C35*(Assms!$C$16+Assms!$C$18)) -> #N/A | D37: =(D35-D28*Assms!$C$31)*Assms!$C$17+(D35*(Assms!$C$16+Assms!$C$18)) -> #N/A | E37: =(E35-E28*Assms!$C$31)*Assms!$C$17+(E35*(Assms!$C$16+Assms!$C$18)) -> #N/A | F37: =(F35-F28*Assms!$C$31)*Assms!$C$17+(F35*(Assms!$C$16+Assms!$C$18)) -> #N/A | G37: =(G35-G28*Assms!$C$31)*Assms!$C$17+(G35*(Assms!$C$16+Assms!$C$18)) -> #N/A | H37: =(H35-H28*Assms!$C$31)*Assms!$C$17+(H35*(Assms!$C$16+Assms!$C$18)) -> #N/A | I37: =(I35-I28*Assms!$C$31)*Assms!$C$17+(I35*(Assms!$C$16+Assms!$C$18)) -> #N/A | J37: =(J35-J28*Assms!$C$31)*Assms!$C$17+(J35*(Assms!$C$16+Assms!$C$18)) -> #N/A | ... AO37: =(AO35-AO28*Assms!$C$31)*Assms!$C$17+(AO35*(Assms!$C$16+Assms!$C$18)) -> #N/A
A38: Per policy Exp | B38: =Assms!C21+Assms!C22 -> 150 | C38: =IF(C29>0,Assms!$C$22*Pricing!C38*C28,0) -> #N/A | D38: =IF(D29>0,Assms!$C$22*Pricing!D38*D28,0) -> #N/A | E38: =IF(E29>0,Assms!$C$22*Pricing!E38*E28,0) -> #N/A | F38: =IF(F29>0,Assms!$C$22*Pricing!F38*F28,0) -> #N/A | G38: =IF(G29>0,Assms!$C$22*Pricing!G38*G28,0) -> #N/A | H38: =IF(H29>0,Assms!$C$22*Pricing!H38*H28,0) -> #N/A | I38: =IF(I29>0,Assms!$C$22*Pricing!I38*I28,0) -> #N/A | J38: =IF(J29>0,Assms!$C$22*Pricing!J38*J28,0) -> #N/A | ... AO38: =IF(AO29>0,Assms!$C$22*Pricing!AO38*AO28,0) -> 0
A39: Death claims | B39: =B29*B26 -> #N/A | C39: =C29*C26 -> #N/A | D39: =D29*D26 -> #N/A | E39: =E29*E26 -> #N/A | F39: =F29*F26 -> #N/A | G39: =G29*G26 -> #N/A | H39: =H29*H26 -> #N/A | I39: =I29*I26 -> #N/A | ... AO39: =AO29*AO26 -> #N/A
A40: Cash value/lapses | B40: =IF(B23=1,B29*B27*B25,"") -> #N/A | C40: =IF(C23=1,C29*C27*C25,"") -> #N/A | D40: =IF(D23=1,D29*D27*D25,"") -> #N/A | E40: =IF(E23=1,E29*E27*E25,"") -> #N/A | F40: =IF(F23=1,F29*F27*F25,"") -> #N/A | G40: =IF(G23=1,G29*G27*G25,"") -> #N/A | H40: =IF(H23=1,H29*H27*H25,"") -> #N/A | I40: =IF(I23=1,I29*I27*I25,"") -> #N/A | ... AO40: =IF(AO23=1,AO29*AO27*AO25,"")
A41: Change in resv | B41: =B30 -> #N/A | C41: =C30-B30 -> #N/A | D41: =D30-C30 -> #N/A | E41: =E30-D30 -> #N/A | F41: =F30-E30 -> #N/A | G41: =G30-F30 -> #N/A | H41: =H30-G30 -> #N/A | I41: =I30-H30 -> #N/A | J41: =J30-I30 -> #N/A | ... AO41: =AO30-AN30 -> #N/A
A43: Pre-tax stat book | B43: =(B35+B36)-SUM(B37:B41) -> #N/A | C43: =(C35+C36)-SUM(C37:C41) -> #N/A | D43: =(D35+D36)-SUM(D37:D41) -> #N/A | E43: =(E35+E36)-SUM(E37:E41) -> #N/A | F43: =(F35+F36)-SUM(F37:F41) -> #N/A | G43: =(G35+G36)-SUM(G37:G41) -> #N/A | H43: =(H35+H36)-SUM(H37:H41) -> #N/A | I43: =(I35+I36)-SUM(I37:I41) -> #N/A | ... AO43: =(AO35+AO36)-SUM(AO37:AO41) -> #N/A
A44: Income tax | B44: =B43*Assms!K13 -> #N/A | C44: =C43*Assms!K13 -> #N/A | D44: =D43*Assms!K13 -> #N/A | E44: =E43*Assms!K13 -> #N/A | F44: =F43*Assms!K13 -> #N/A | G44: =G43*Assms!K13 -> #N/A | H44: =H43*Assms!K13 -> #N/A | I44: =I43*Assms!K13 -> #N/A | J44: =J43*Assms!K13 -> #N/A | K44: =K43*Assms!K13 -> #N/A | L44: =L43*Assms!K13 -> #N/A | M44: =M43*Assms!K13 -> #N/A | N44: =N43*Assms!K13 -> #N/A | O44: =O43*Assms!K13 -> #N/A | P44: =P43*Assms!K13 -> #N/A | Q44: =Q43*Assms!K13 -> #N/A | R44: =R43*Assms!K13 -> #N/A | S44: =S43*Assms!K13 -> #N/A | T44: =T43*Assms!K13 -> #N/A | U44: =U43*Assms!K13 -> #N/A | V44: =V43*Assms!K13 -> #N/A | W44: =W43*Assms!K13 -> #N/A | X44: =X43*Assms!K13 -> #N/A | Y44: =Y43*Assms!K13 -> #N/A | Z44: =Z43*Assms!K13 -> #N/A | AA44: =AA43*Assms!K13 -> #N/A | AB44: =AB43*Assms!K13 -> #N/A | AC44: =AC43*Assms!K13 -> #N/A | AD44: =AD43*Assms!K13 -> #N/A | AE44: =AE43*Assms!K13 -> #N/A | AF44: =AF43*Assms!K13 -> #N/A | AG44: =AG43*Assms!K13 -> #N/A | AH44: =AH43*Assms!K13 -> #N/A | AI44: =AI43*Assms!K13 -> #N/A | AJ44: =AJ43*Assms!K13 -> #N/A | AK44: =AK43*Assms!K13 -> #N/A | AL44: =AL43*Assms!K13 -> #N/A | AM44: =AM43*Assms!K13 -> #N/A | AN44: =AN43*Assms!K13 -> #N/A | AO44: =AO43*Assms!K13 -> #N/A
A45: DAC tax payments | B45: =Pricing!B105*'Alt1'!$B$1/Pricing!$K$10 -> #N/A | C45: =Pricing!C105*'Alt1'!$B$1/Pricing!$K$10 -> #N/A | D45: =Pricing!D105*'Alt1'!$B$1/Pricing!$K$10 -> #N/A | E45: =Pricing!E105*'Alt1'!$B$1/Pricing!$K$10 -> #N/A | F45: =Pricing!F105*'Alt1'!$B$1/Pricing!$K$10 -> #N/A | G45: =Pricing!G105*'Alt1'!$B$1/Pricing!$K$10 -> #N/A | H45: =Pricing!H105*'Alt1'!$B$1/Pricing!$K$10 -> #N/A | I45: =Pricing!I105*'Alt1'!$B$1/Pricing!$K$10 -> #N/A | ... AO45: =Pricing!AO105*'Alt1'!$B$1/Pricing!$K$10 -> #N/A
...

Sheet Alt3
A1: Calculate IRR with Alt3 premium | B1: =Pricing!N10 -> #N/A | D1: PV premium | E1: =NPV(Assms!K14,C35:AO35)+B35 -> #N/A
D2: PV book pft | E2: =NPV(Assms!K14,B46:AO46) -> #N/A
A3: Last year of coverage requested (BOY age): | B3: =Pricing!M1 -> 0 | D3: Margin | E3: =E2/E1 -> #N/A
A4: Last year of custom design model (BOY age) | B4: =Pricing!M2 -> 22 | D4: IRR | E4: =IRR(B55:AO55,8%) -> #VALUE!
A5: Last year of coverage priced/shown | B5: =Pricing!M3 -> 0 | D5: Stat strain | E5: =B46/B35 -> #N/A
A7: Policy Year | B7: 1 | C7: =B7+1 -> 2 | D7: =C7+1 -> 3 | E7: =D7+1 -> 4 | F7: =E7+1 -> 5 | G7: =F7+1 -> 6 | H7: =G7+1 -> 7 | I7: =H7+1 -> 8 | J7: =I7+1 -> 9 | ... AO7: =AN7+1 -> 40
A8: Age of insured | B8: =Pricing!B36 -> 0 | C8: =Pricing!C36 -> 1 | D8: =Pricing!D36 -> 2 | E8: =Pricing!E36 -> 3 | F8: =Pricing!F36 -> 4 | G8: =Pricing!G36 -> 5 | H8: =Pricing!H36 -> 6 | I8: =Pricing!I36 -> 7 | ... AO8: =Pricing!AO36 -> 39
A9: Coverage active? | B9: =Pricing!B37 -> 1 | C9: =Pricing!C37 -> 1 | D9: =Pricing!D37 -> 1 | E9: =Pricing!E37 -> 1 | F9: =Pricing!F37 -> 1 | G9: =Pricing!G37 -> 1 | H9: =Pricing!H37 -> 1 | I9: =Pricing!I37 -> 1 | ... AO9: =Pricing!AO37 -> 0
A10: Inflation factor (cumulative since issue) | B10: 1 | C10: =B10*(1+Assms!C23) -> 1.02 | D10: =C10*(1+Assms!C23) -> 1.0404 | E10: =D10*(1+Assms!C23) -> 1.061208 | F10: =E10*(1+Assms!C23) -> 1.0824322 | G10: =F10*(1+Assms!C23) -> 1.1040808 | H10: =G10*(1+Assms!C23) -> 1.1261624 | I10: =H10*(1+Assms!C23) -> 1.1486857 | J10: =I10*(1+Assms!C23) -> 1.1716594 | K10: =J10*(1+Assms!C23) -> 1.1950926 | L10: =K10*(1+Assms!C23) -> 1.2189944 | M10: =L10*(1+Assms!C23) -> 1.2433743 | N10: =M10*(1+Assms!C23) -> 1.2682418 | O10: =N10*(1+Assms!C23) -> 1.2936066 | P10: =O10*(1+Assms!C23) -> 1.3194788 | Q10: =P10*(1+Assms!C23) -> 1.3458683 | R10: =Q10*(1+Assms!C23) -> 1.3727857 | S10: =R10*(1+Assms!C23) -> 1.4002414 | T10: =S10*(1+Assms!C23) -> 1.4282462 | U10: =T10*(1+Assms!C23) -> 1.4568112 | V10: =U10*(1+Assms!C23) -> 1.4859474 | W10: =V10*(1+Assms!C23) -> 1.5156663 | X10: =W10*(1+Assms!C23) -> 1.5459797 | Y10: =X10*(1+Assms!C23) -> 1.5768993 | Z10: =Y10*(1+Assms!C23) -> 1.6084372 | AA10: =Z10*(1+Assms!C23) -> 1.640606 | AB10: =AA10*(1+Assms!C23) -> 1.6734181 | AC10: =AB10*(1+Assms!C23) -> 1.7068865 | AD10: =AC10*(1+Assms!C23) -> 1.7410242 | AE10: =AD10*(1+Assms!C23) -> 1.7758447 | AF10: =AE10*(1+Assms!C23) -> 1.8113616 | AG10: =AF10*(1+Assms!C23) -> 1.8475888 | AH10: =AG10*(1+Assms!C23) -> 1.8845406 | AI10: =AH10*(1+Assms!C23) -> 1.9222314 | AJ10: =AI10*(1+Assms!C23) -> 1.960676 | AK10: =AJ10*(1+Assms!C23) -> 1.9998896 | AL10: =AK10*(1+Assms!C23) -> 2.0398873 | AM10: =AL10*(1+Assms!C23) -> 2.0806851 | AN10: =AM10*(1+Assms!C23) -> 2.1222988 | AO10: =AN10*(1+Assms!C23) -> 2.1647448
A11: Expected mortality rate | B11: =Pricing!B42 -> #N/A | C11: =Pricing!C42 -> #N/A | D11: =Pricing!D42 -> #N/A | E11: =Pricing!E42 -> #N/A | F11: =Pricing!F42 -> #N/A | G11: =Pricing!G42 -> #N/A | H11: =Pricing!H42 -> #N/A | I11: =Pricing!I42 -> #N/A | ... AO11: =Pricing!AO42 -> #N/A
A12: Lapse rate with excess | B12: =Pricing!B59 -> 0.04 | C12: =Pricing!C59 -> 0.05 | D12: =Pricing!D59 -> 0.05 | E12: =Pricing!E59 -> 0.04 | F12: =Pricing!F59 -> 0.04 | G12: =Pricing!G59 -> 0.04 | H12: =Pricing!H59 -> 0.03 | I12: =Pricing!I59 -> 0.03 | ... AO12: =Pricing!AO59 -> 0.02
A13: EOY survival rate before that yr's Qx and Lx | B13: 1 | C13: =B13*(1-B12-B11) -> #N/A | D13: =C13*(1-C12-C11) -> #N/A | E13: =D13*(1-D12-D11) -> #N/A | F13: =E13*(1-E12-E11) -> #N/A | G13: =F13*(1-F12-F11) -> #N/A | H13: =G13*(1-G12-G11) -> #N/A | I13: =H13*(1-H12-H11) -> #N/A | J13: =I13*(1-I12-I11) -> #N/A | ... AO13: =AN13*(1-AN12-AN11) -> #N/A
A14: Survival rate for coverage period | B14: =IF(B9=1,B13,0) -> 1 | C14: =IF(C9=1,C13,0) -> #N/A | D14: =IF(D9=1,D13,0) -> #N/A | E14: =IF(E9=1,E13,0) -> #N/A | F14: =IF(F9=1,F13,0) -> #N/A | G14: =IF(G9=1,G13,0) -> #N/A | H14: =IF(H9=1,H13,0) -> #N/A | I14: =IF(I9=1,I13,0) -> #N/A | ... AO14: =IF(AO9=1,AO13,0) -> 0
A16: Death benefit | B16: =Pricing!B39 -> 842000 | C16: =Pricing!C39 -> 837000 | D16: =Pricing!D39 -> 830000 | E16: =Pricing!E39 -> 821000 | F16: =Pricing!F39 -> 811000 | G16: =Pricing!G39 -> 798000 | H16: =Pricing!H39 -> 784000 | I16: =Pricing!I39 -> 767000 | ... AO16: =Pricing!AO39 -> 0
A17: Inforce death benefit (beg of year) | B17: =B16*B14 -> 842000 | C17: =C16*C14 -> #N/A | D17: =D16*D14 -> #N/A | E17: =E16*E14 -> #N/A | F17: =F16*F14 -> #N/A | G17: =G16*G14 -> #N/A | H17: =H16*H14 -> #N/A | I17: =I16*I14 -> #N/A | ... AO17: =AO16*AO14 -> 0
A18: Expected death claims (EOY before lapses) | B18: =B17*B11 -> #N/A | C18: =C17*C11 -> #N/A | D18: =D17*D11 -> #N/A | E18: =E17*E11 -> #N/A | F18: =F17*F11 -> #N/A | G18: =G17*G11 -> #N/A | H18: =H17*H11 -> #N/A | I18: =I17*I11 -> #N/A | ... AO18: =AO17*AO11 -> #N/A
A19: Inforce premium collected (beg of year) | B19: =$B$1*B14 -> #N/A | C19: =$B$1*C14 -> #N/A | D19: =$B$1*D14 -> #N/A | E19: =$B$1*E14 -> #N/A | F19: =$B$1*F14 -> #N/A | G19: =$B$1*G14 -> #N/A | H19: =$B$1*H14 -> #N/A | I19: =$B$1*I14 -> #N/A | ... AO19: =$B$1*AO14 -> #N/A
A20: Per Policy expenses | B20: =Assms!C21+Assms!C22 -> 150 | C20: =Assms!C22*C10*C14 -> #N/A | D20: =Assms!C22*D10*D14 -> #N/A | E20: =Assms!C22*E10*E14 -> #N/A | F20: =Assms!C22*F10*F14 -> #N/A | G20: =Assms!C22*G10*G14 -> #N/A | H20: =Assms!C22*H10*H14 -> #N/A | I20: =Assms!C22*I10*I14 -> #N/A | J20: =Assms!C22*J10*J14 -> #N/A | K20: =Assms!C22*K10*K14 -> #N/A | L20: =Assms!C22*L10*L14 -> #N/A | M20: =Assms!C22*M10*M14 -> #N/A | N20: =Assms!C22*N10*N14 -> #N/A | O20: =Assms!C22*O10*O14 -> #N/A | P20: =Assms!C22*P10*P14 -> #N/A | Q20: =Assms!C22*Q10*Q14 -> #N/A | R20: =Assms!C22*R10*R14 -> #N/A | S20: =Assms!C22*S10*S14 -> #N/A | T20: =Assms!C22*T10*T14 -> #N/A | U20: =Assms!C22*U10*U14 -> #N/A | V20: =Assms!C22*V10*V14 -> #N/A | W20: =Assms!C22*W10*W14 -> #N/A | X20: =Assms!C22*X10*X14 -> #N/A | Y20: =Assms!C22*Y10*Y14 -> 0 | Z20: =Assms!C22*Z10*Z14 -> 0 | AA20: =Assms!C22*AA10*AA14 -> 0 | AB20: =Assms!C22*AB10*AB14 -> 0 | AC20: =Assms!C22*AC10*AC14 -> 0 | AD20: =Assms!C22*AD10*AD14 -> 0 | AE20: =Assms!C22*AE10*AE14 -> 0 | AF20: =Assms!C22*AF10*AF14 -> 0 | AG20: =Assms!C22*AG10*AG14 -> 0 | AH20: =Assms!C22*AH10*AH14 -> 0 | AI20: =Assms!C22*AI10*AI14 -> 0 | AJ20: =Assms!C22*AJ10*AJ14 -> 0 | AK20: =Assms!C22*AK10*AK14 -> 0 | AL20: =Assms!C22*AL10*AL14 -> 0 | AM20: =Assms!C22*AM10*AM14 -> 0 | AN20: =Assms!C22*AN10*AN14 -> 0 | AO20: =Assms!C22*AO10*AO14 -> 0
A22: Profitability Calculation
A23: Inforce? | B23: =StatV!B12 -> 1 | C23: =StatV!C12 -> 1 | D23: =StatV!D12 -> 1 | E23: =StatV!E12 -> 1 | F23: =StatV!F12 -> 1 | G23: =StatV!G12 -> 1 | H23: =StatV!H12 -> 1 | I23: =StatV!I12 -> 1 | ... AO23: =StatV!AO12 -> 0
A24: Reserve per DB inforce | B24: =StatV!B203 -> #N/A | C24: =StatV!C203 -> #N/A | D24: =StatV!D203 -> #N/A | E24: =StatV!E203 -> #N/A | F24: =StatV!F203 -> #N/A | G24: =StatV!G203 -> #N/A | H24: =StatV!H203 -> #N/A | I24: =StatV!I203 -> #N/A | ... AO24: =StatV!AO203 -> #N/A
A25: Cash Value per DB inforce | B25: =CashValue!C39 -> #N/A | C25: =CashValue!D39 -> #N/A | D25: =CashValue!E39 -> #N/A | E25: =CashValue!F39 -> #N/A | F25: =CashValue!G39 -> #N/A | G25: =CashValue!H39 -> #N/A | H25: =CashValue!I39 -> #N/A | I25: =CashValue!J39 -> #N/A | ... AO25: =CashValue!AP39 -> #N/A
A26: Mortality rate | B26: =Pricing!B72 -> #N/A | C26: =Pricing!C72 -> #N/A | D26: =Pricing!D72 -> #N/A | E26: =Pricing!E72 -> #N/A | F26: =Pricing!F72 -> #N/A | G26: =Pricing!G72 -> #N/A | H26: =Pricing!H72 -> #N/A | I26: =Pricing!I72 -> #N/A | ... AO26: =Pricing!AO72 -> #N/A
A27: Lapse rate | B27: =Pricing!B69 -> 0.04 | C27: =Pricing!C69 -> 0.05 | D27: =Pricing!D69 -> 0.05 | E27: =Pricing!E69 -> 0.04 | F27: =Pricing!F69 -> 0.04 | G27: =Pricing!G69 -> 0.04 | H27: =Pricing!H69 -> 0.03 | I27: =Pricing!I69 -> 0.03 | ... AO27: =Pricing!AO69 -> 0.02
A28: tPx (beg yr) | B28: 1 | C28: =IF(C23=1,B28*(1-B26-B27),0) -> #N/A | D28: =IF(D23=1,C28*(1-C26-C27),0) -> #N/A | E28: =IF(E23=1,D28*(1-D26-D27),0) -> #N/A | F28: =IF(F23=1,E28*(1-E26-E27),0) -> #N/A | G28: =IF(G23=1,F28*(1-F26-F27),0) -> #N/A | H28: =IF(H23=1,G28*(1-G26-G27),0) -> #N/A | I28: =IF(I23=1,H28*(1-H26-H27),0) -> #N/A | J28: =IF(J23=1,I28*(1-I26-I27),0) -> #N/A | ... AO28: =IF(AO23=1,AN28*(1-AN26-AN27),0) -> 0
A29: Inforce DB (BOY) | B29: =Pricing!B39*B28 -> 842000 | C29: =Pricing!C39*C28 -> #N/A | D29: =Pricing!D39*D28 -> #N/A | E29: =Pricing!E39*E28 -> #N/A | F29: =Pricing!F39*F28 -> #N/A | G29: =Pricing!G39*G28 -> #N/A | H29: =Pricing!H39*H28 -> #N/A | I29: =Pricing!I39*I28 -> #N/A | ... AO29: =Pricing!AO39*AO28 -> 0
A30: Reserve inforce | B30: =B29*B24 -> #N/A | C30: =C29*C24 -> #N/A | D30: =D29*D24 -> #N/A | E30: =E29*E24 -> #N/A | F30: =F29*F24 -> #N/A | G30: =G29*G24 -> #N/A | H30: =H29*H24 -> #N/A | I30: =I29*I24 -> #N/A | ... AN30: =AN29*AN24 -> #N/A | AO30: 0
A31: CV inforce | B31: =B29*B25 -> #N/A | C31: =C29*C25 -> #N/A | D31: =D29*D25 -> #N/A | E31: =E29*E25 -> #N/A | F31: =F29*F25 -> #N/A | G31: =G29*G25 -> #N/A | H31: =H29*H25 -> #N/A | I31: =I29*I25 -> #N/A | ... AO31: =AO29*AO25 -> #N/A
A33: Stat book profit (customized policy)
A34: Policy Year | B34: 1 | C34: =B34+1 -> 2 | D34: =C34+1 -> 3 | E34: =D34+1 -> 4 | F34: =E34+1 -> 5 | G34: =F34+1 -> 6 | H34: =G34+1 -> 7 | I34: =H34+1 -> 8 | J34: =I34+1 -> 9 | ... AO34: =AN34+1 -> 40
A35: Premiums | B35: =$B$1*B28 -> #N/A | C35: =$B$1*C28 -> #N/A | D35: =$B$1*D28 -> #N/A | E35: =$B$1*E28 -> #N/A | F35: =$B$1*F28 -> #N/A | G35: =$B$1*G28 -> #N/A | H35: =$B$1*H28 -> #N/A | I35: =$B$1*I28 -> #N/A | ... AO35: =$B$1*AO28 -> #N/A
